2020-01-21 17:37:31,634 INFO: Microblog startup [in /Users/alfredtingey/news_agg_app/app/__init__.py:48]
2020-01-21 17:49:13,588 INFO: Microblog startup [in /Users/alfredtingey/news_agg_app/app/__init__.py:46]
2020-01-21 17:49:21,406 INFO: Microblog startup [in /Users/alfredtingey/news_agg_app/app/__init__.py:46]
2020-01-21 17:52:52,930 INFO: Microblog startup [in /Users/alfredtingey/news_agg_app/app/__init__.py:46]
2020-01-21 17:54:39,644 INFO: Microblog startup [in /Users/alfredtingey/news_agg_app/app/__init__.py:46]
2020-01-21 18:08:39,543 INFO: Microblog startup [in /Users/alfredtingey/news_agg_app/app/__init__.py:46]
2020-01-22 14:06:53,448 INFO: Microblog startup [in /Users/alfredtingey/news_agg_app/app/__init__.py:46]
2020-01-22 14:29:27,136 INFO: Microblog startup [in /Users/alfredtingey/news_agg_app/app/__init__.py:46]
2020-01-22 16:42:20,763 INFO: Microblog startup [in /Users/alfredtingey/news_agg_app/app/__init__.py:46]
2020-01-22 19:48:43,233 INFO: Microblog startup [in /Users/alfredtingey/news_agg_app/app/__init__.py:46]
2020-01-28 22:44:45,912 INFO: Microblog startup [in /Users/alfredtingey/news_agg_app/app/__init__.py:46]
2020-01-28 22:45:42,235 INFO: Microblog startup [in /Users/alfredtingey/news_agg_app/app/__init__.py:46]
2020-01-28 22:57:15,882 INFO: Microblog startup [in /Users/alfredtingey/news_agg_app/app/__init__.py:46]
2020-01-28 22:57:21,283 ERROR: Exception on /news_sites [GET] [in /Users/alfredtingey/news_agg_app/venv/lib/python3.7/site-packages/flask/app.py:1891]
Traceback (most recent call last):
  File "/Users/alfredtingey/news_agg_app/venv/lib/python3.7/site-packages/flask/app.py", line 2446, in wsgi_app
    response = self.full_dispatch_request()
  File "/Users/alfredtingey/news_agg_app/venv/lib/python3.7/site-packages/flask/app.py", line 1951, in full_dispatch_request
    rv = self.handle_user_exception(e)
  File "/Users/alfredtingey/news_agg_app/venv/lib/python3.7/site-packages/flask/app.py", line 1820, in handle_user_exception
    reraise(exc_type, exc_value, tb)
  File "/Users/alfredtingey/news_agg_app/venv/lib/python3.7/site-packages/flask/_compat.py", line 39, in reraise
    raise value
  File "/Users/alfredtingey/news_agg_app/venv/lib/python3.7/site-packages/flask/app.py", line 1949, in full_dispatch_request
    rv = self.dispatch_request()
  File "/Users/alfredtingey/news_agg_app/venv/lib/python3.7/site-packages/flask/app.py", line 1935, in dispatch_request
    return self.view_functions[rule.endpoint](**req.view_args)
  File "/Users/alfredtingey/news_agg_app/venv/lib/python3.7/site-packages/flask_login/utils.py", line 261, in decorated_view
    return func(*args, **kwargs)
  File "/Users/alfredtingey/news_agg_app/app/routes.py", line 159, in news_sites
    return render_template("index.html", title='News', posts=posts.items,
NameError: name 'posts' is not defined
2020-01-28 22:57:26,128 ERROR: Exception on /news_sites [GET] [in /Users/alfredtingey/news_agg_app/venv/lib/python3.7/site-packages/flask/app.py:1891]
Traceback (most recent call last):
  File "/Users/alfredtingey/news_agg_app/venv/lib/python3.7/site-packages/flask/app.py", line 2446, in wsgi_app
    response = self.full_dispatch_request()
  File "/Users/alfredtingey/news_agg_app/venv/lib/python3.7/site-packages/flask/app.py", line 1951, in full_dispatch_request
    rv = self.handle_user_exception(e)
  File "/Users/alfredtingey/news_agg_app/venv/lib/python3.7/site-packages/flask/app.py", line 1820, in handle_user_exception
    reraise(exc_type, exc_value, tb)
  File "/Users/alfredtingey/news_agg_app/venv/lib/python3.7/site-packages/flask/_compat.py", line 39, in reraise
    raise value
  File "/Users/alfredtingey/news_agg_app/venv/lib/python3.7/site-packages/flask/app.py", line 1949, in full_dispatch_request
    rv = self.dispatch_request()
  File "/Users/alfredtingey/news_agg_app/venv/lib/python3.7/site-packages/flask/app.py", line 1935, in dispatch_request
    return self.view_functions[rule.endpoint](**req.view_args)
  File "/Users/alfredtingey/news_agg_app/venv/lib/python3.7/site-packages/flask_login/utils.py", line 261, in decorated_view
    return func(*args, **kwargs)
  File "/Users/alfredtingey/news_agg_app/app/routes.py", line 159, in news_sites
    return render_template("index.html", title='News', posts=posts.items,
NameError: name 'posts' is not defined
2020-01-28 22:58:17,021 INFO: Microblog startup [in /Users/alfredtingey/news_agg_app/app/__init__.py:46]
2020-01-28 23:16:51,140 INFO: Microblog startup [in /Users/alfredtingey/news_agg_app/app/__init__.py:46]
2020-01-28 23:22:41,154 INFO: Microblog startup [in /Users/alfredtingey/news_agg_app/app/__init__.py:46]
2020-01-28 23:24:46,230 INFO: Microblog startup [in /Users/alfredtingey/news_agg_app/app/__init__.py:46]
2020-01-28 23:25:38,491 INFO: Microblog startup [in /Users/alfredtingey/news_agg_app/app/__init__.py:46]
2020-01-28 23:26:13,238 INFO: Microblog startup [in /Users/alfredtingey/news_agg_app/app/__init__.py:46]
2020-01-29 00:18:41,456 INFO: Microblog startup [in /Users/alfredtingey/news_agg_app/app/__init__.py:46]
2020-01-29 00:19:14,507 INFO: Microblog startup [in /Users/alfredtingey/news_agg_app/app/__init__.py:46]
2020-01-29 00:22:29,770 INFO: Microblog startup [in /Users/alfredtingey/news_agg_app/app/__init__.py:46]
2020-01-29 00:22:43,865 ERROR: Exception on /news_sites [GET] [in /Users/alfredtingey/news_agg_app/venv/lib/python3.7/site-packages/flask/app.py:1891]
Traceback (most recent call last):
  File "/Users/alfredtingey/news_agg_app/venv/lib/python3.7/site-packages/flask/app.py", line 2446, in wsgi_app
    response = self.full_dispatch_request()
  File "/Users/alfredtingey/news_agg_app/venv/lib/python3.7/site-packages/flask/app.py", line 1951, in full_dispatch_request
    rv = self.handle_user_exception(e)
  File "/Users/alfredtingey/news_agg_app/venv/lib/python3.7/site-packages/flask/app.py", line 1820, in handle_user_exception
    reraise(exc_type, exc_value, tb)
  File "/Users/alfredtingey/news_agg_app/venv/lib/python3.7/site-packages/flask/_compat.py", line 39, in reraise
    raise value
  File "/Users/alfredtingey/news_agg_app/venv/lib/python3.7/site-packages/flask/app.py", line 1949, in full_dispatch_request
    rv = self.dispatch_request()
  File "/Users/alfredtingey/news_agg_app/venv/lib/python3.7/site-packages/flask/app.py", line 1935, in dispatch_request
    return self.view_functions[rule.endpoint](**req.view_args)
  File "/Users/alfredtingey/news_agg_app/venv/lib/python3.7/site-packages/flask_login/utils.py", line 261, in decorated_view
    return func(*args, **kwargs)
  File "/Users/alfredtingey/news_agg_app/app/routes.py", line 159, in news_sites
    news = News.get_news()
NameError: name 'News' is not defined
2020-01-29 00:22:48,423 ERROR: Exception on /news_sites [GET] [in /Users/alfredtingey/news_agg_app/venv/lib/python3.7/site-packages/flask/app.py:1891]
Traceback (most recent call last):
  File "/Users/alfredtingey/news_agg_app/venv/lib/python3.7/site-packages/flask/app.py", line 2446, in wsgi_app
    response = self.full_dispatch_request()
  File "/Users/alfredtingey/news_agg_app/venv/lib/python3.7/site-packages/flask/app.py", line 1951, in full_dispatch_request
    rv = self.handle_user_exception(e)
  File "/Users/alfredtingey/news_agg_app/venv/lib/python3.7/site-packages/flask/app.py", line 1820, in handle_user_exception
    reraise(exc_type, exc_value, tb)
  File "/Users/alfredtingey/news_agg_app/venv/lib/python3.7/site-packages/flask/_compat.py", line 39, in reraise
    raise value
  File "/Users/alfredtingey/news_agg_app/venv/lib/python3.7/site-packages/flask/app.py", line 1949, in full_dispatch_request
    rv = self.dispatch_request()
  File "/Users/alfredtingey/news_agg_app/venv/lib/python3.7/site-packages/flask/app.py", line 1935, in dispatch_request
    return self.view_functions[rule.endpoint](**req.view_args)
  File "/Users/alfredtingey/news_agg_app/venv/lib/python3.7/site-packages/flask_login/utils.py", line 261, in decorated_view
    return func(*args, **kwargs)
  File "/Users/alfredtingey/news_agg_app/app/routes.py", line 159, in news_sites
    news = News.get_news()
NameError: name 'News' is not defined
2020-01-29 00:26:01,586 INFO: Microblog startup [in /Users/alfredtingey/news_agg_app/app/__init__.py:46]
2020-01-29 00:26:07,693 ERROR: Exception on /news_sites [GET] [in /Users/alfredtingey/news_agg_app/venv/lib/python3.7/site-packages/flask/app.py:1891]
Traceback (most recent call last):
  File "/Users/alfredtingey/news_agg_app/venv/lib/python3.7/site-packages/flask/app.py", line 2446, in wsgi_app
    response = self.full_dispatch_request()
  File "/Users/alfredtingey/news_agg_app/venv/lib/python3.7/site-packages/flask/app.py", line 1951, in full_dispatch_request
    rv = self.handle_user_exception(e)
  File "/Users/alfredtingey/news_agg_app/venv/lib/python3.7/site-packages/flask/app.py", line 1820, in handle_user_exception
    reraise(exc_type, exc_value, tb)
  File "/Users/alfredtingey/news_agg_app/venv/lib/python3.7/site-packages/flask/_compat.py", line 39, in reraise
    raise value
  File "/Users/alfredtingey/news_agg_app/venv/lib/python3.7/site-packages/flask/app.py", line 1949, in full_dispatch_request
    rv = self.dispatch_request()
  File "/Users/alfredtingey/news_agg_app/venv/lib/python3.7/site-packages/flask/app.py", line 1935, in dispatch_request
    return self.view_functions[rule.endpoint](**req.view_args)
  File "/Users/alfredtingey/news_agg_app/venv/lib/python3.7/site-packages/flask_login/utils.py", line 261, in decorated_view
    return func(*args, **kwargs)
  File "/Users/alfredtingey/news_agg_app/app/routes.py", line 159, in news_sites
    news = News.get_news()
TypeError: get_news() missing 1 required positional argument: 'self'
2020-01-29 00:28:07,646 INFO: Microblog startup [in /Users/alfredtingey/news_agg_app/app/__init__.py:46]
2020-01-29 00:28:25,262 INFO: Microblog startup [in /Users/alfredtingey/news_agg_app/app/__init__.py:46]
